<?xml version="1.0"?>
<robot  xmlns:xacro="http://ros.org/wiki/xacro" name="diff_robot">
 

  <!-- Base Link (main body) -->
  <link name="base_link">
    <visual>
      <geometry>
        <box size="0.4 0.3 0.1"/>
      </geometry>
      <origin xyz="0 0 0.05"/>
      <material name="blue">
        <color rgba="0 0 1 1"/>
      </material>
    </visual>
    <collision>
      <geometry>
        <box size="0.4 0.3 0.1"/>
      </geometry>
      <origin xyz="0 0 0.05"/>
    </collision>
  </link>

  <!-- Camera Link  -->
  <link name="camera_link">
    <visual>
      <geometry>
        <box size="0.05 0.05 0.01"/>
      </geometry>
      <origin xyz="0 0 0"/>
      <material name="black">
        <color rgba="1 0 0 1"/>
      </material>
    </visual>
    <collision>
      <geometry>
        <box size="0.05 0.05 0.05"/>
      </geometry>
      <origin xyz="0 0 0.05"/>
    </collision>
  </link>

  <!-- Lidar Link  -->
  <link name="lidar_link">
    <visual>
      <geometry>
        <cylinder radius="0.05" length="0.05"/>
      </geometry>
      <origin xyz="0 0 0"/>
      <material name="black">
        <color rgba="1 0 0 1"/>
      </material>
    </visual>
    <collision>
      <geometry>
        <box size="0.05 0.05 0.05"/>
      </geometry>
      <origin xyz="0 0 0.05"/>
    </collision>
  </link>
 
  <!-- Left Wheel -->
  <link name="left_wheel">
    <visual>
      <geometry>
        <cylinder length="0.05" radius="0.05"/>
      </geometry>
      <origin xyz="0 0 0" rpy="0 1.5708 0"/>
      <material name="black">
        <color rgba="0 0 0 1"/>
      </material>
    </visual>
    <collision>
      <geometry>
        <cylinder length="0.05" radius="0.05"/>
      </geometry>
      <origin xyz="0 0 0" rpy="0 1.5708 0"/>
    </collision>
  </link>

  
 
  <!-- Right Wheel -->
  <link name="right_wheel">
    <visual>
      <geometry>
        <cylinder length="0.05" radius="0.05"/>
      </geometry>
      <origin xyz="0 0 0" rpy="0 1.5708 0"/>
      <material name="black">
        <color rgba="0 0 0 1"/>
      </material>
    </visual>
    <collision>
      <geometry>
        <cylinder length="0.05" radius="0.05"/>
      </geometry>
      <origin xyz="0 0 0" rpy="0 1.5708 0"/>
    </collision>
  </link>
 
  <!-- Caster Wheel -->
  <link name="caster_wheel">
    <visual>
      <geometry>
        <sphere radius="0.03"/>
      </geometry>
      <origin xyz="0 -0.1 0.03"/>
      <material name="gray">
        <color rgba="0.5 0.5 0.5 1"/>
      </material>
    </visual>
    <collision>
      <geometry>
        <sphere radius="0.03"/>
      </geometry>
      <origin xyz="0 -0.1 0.03"/>
    </collision>
  </link>
 
  <!-- Joints -->
  <joint name="left_wheel_joint" type="continuous">
    <parent link="base_link"/>
    <child link="left_wheel"/>
    <origin xyz="-0.1 0.15 0.01" rpy="0 0 1.57"/>
    <axis xyz="1 0 0"/>
  </joint>
 
  <joint name="right_wheel_joint" type="continuous">
    <parent link="base_link"/>
    <child link="right_wheel"/>
    <origin xyz="-0.1 -0.15 0.01" rpy="0 0 1.57"/>
    <axis xyz="1 0 0"/>
  </joint>
 
  <joint name="caster_joint" type="fixed">
    <parent link="base_link"/>
    <child link="caster_wheel"/>
    <origin xyz="0.0 0.0 -0.05" rpy="0 0 1.57"/>
    <axis xyz="0 1 0"/>
  </joint>

  <joint name="camera_joint" type="fixed">
    <parent link="base_link"/>
    <child link="camera_link"/>
    <origin xyz="0.2 0 0.1" rpy="0 1.57 0"/>
    <axis xyz="0 1 0"/>
  </joint>

   <joint name="lidar_joint" type="fixed">
    <parent link="base_link"/>
    <child link="lidar_link"/>
    <origin xyz="0.1 0 0.12" rpy="0 0 0"/>
    <axis xyz="0 1 0"/>
  </joint>
 
</robot>
 